2021-04-15 at 15:31:21 🔖   INFO     Found additional log level customization: 💪   SUCCESS                                                💻 log.py@init:75 ⏰ 0:00:00.398312
2021-04-15 at 15:31:21 🔖   INFO     Found additional log level customization: 👀   WARN                                                   💻 log.py@init:75 ⏰ 0:00:00.399490
2021-04-15 at 15:31:21 🔖   INFO     Found additional log level customization: 🔖   INFO                                                   💻 log.py@init:75 ⏰ 0:00:00.399966
2021-04-15 at 15:31:21 🔖   INFO     Found additional log level customization: ❌   ERROR                                                  💻 log.py@init:75 ⏰ 0:00:00.400263
2021-04-15 at 15:31:21 🔖   INFO     Found additional log level customization: 🎯   NOTICE                                                 💻 log.py@init:75 ⏰ 0:00:00.400504
2021-04-15 at 15:31:21 🔖   INFO     Found additional log level customization: 💩   SPAM                                                   💻 log.py@init:75 ⏰ 0:00:00.400718
2021-04-15 at 15:31:21 🔖   INFO     Found additional log level customization: 📝   VERBOSE                                                💻 log.py@init:75 ⏰ 0:00:00.400914
2021-04-15 at 15:31:21 🔖   INFO     Found additional log level customization: 💥   CRITICAL                                               💻 log.py@init:75 ⏰ 0:00:00.401078
2021-04-15 at 15:31:21 🎯   NOTICE   JWT authentication disabled                                                                          💻 __init__.py@api:38 ⏰ 0:00:00.401257
2021-04-15 at 15:31:21 🎯   NOTICE   HTTPS not set                                                                                        💻 __init__.py@api:44 ⏰ 0:00:00.401405
2021-04-15 at 15:31:21 🎯   NOTICE   Elastic APM disabled                                                                                 💻 __init__.py@api:50 ⏰ 0:00:00.401546
2021-04-15 at 15:31:21 🔖   INFO     Check connection to http://localhost:9000/polycube/v1                                                💻 polycube.py@__init__:25 ⏰ 0:00:00.407634
2021-04-15 at 15:31:21 ❌   ERROR    Connection with polycube at localhost:9000 not possible                                              💻 polycube.py@__init__:31 ⏰ 0:00:00.410159
Traceback (most recent call last):
  File "/home/jicg/.venv/carrega/lib/python3.9/site-packages/urllib3/connection.py", line 159, in _new_conn
    conn = connection.create_connection(
  File "/home/jicg/.venv/carrega/lib/python3.9/site-packages/urllib3/util/connection.py", line 84, in create_connection
    raise err
  File "/home/jicg/.venv/carrega/lib/python3.9/site-packages/urllib3/util/connection.py", line 74, in create_connection
    sock.connect(sa)
ConnectionRefusedError: [Errno 111] Connection refused

During handling of the above exception, another exception occurred:

Traceback (most recent call last):
  File "/home/jicg/.venv/carrega/lib/python3.9/site-packages/urllib3/connectionpool.py", line 670, in urlopen
    httplib_response = self._make_request(
  File "/home/jicg/.venv/carrega/lib/python3.9/site-packages/urllib3/connectionpool.py", line 392, in _make_request
    conn.request(method, url, **httplib_request_kw)
  File "/usr/lib/python3.9/http/client.py", line 1253, in request
    self._send_request(method, url, body, headers, encode_chunked)
  File "/usr/lib/python3.9/http/client.py", line 1299, in _send_request
    self.endheaders(body, encode_chunked=encode_chunked)
  File "/usr/lib/python3.9/http/client.py", line 1248, in endheaders
    self._send_output(message_body, encode_chunked=encode_chunked)
  File "/usr/lib/python3.9/http/client.py", line 1008, in _send_output
    self.send(msg)
  File "/usr/lib/python3.9/http/client.py", line 948, in send
    self.connect()
  File "/home/jicg/.venv/carrega/lib/python3.9/site-packages/urllib3/connection.py", line 187, in connect
    conn = self._new_conn()
  File "/home/jicg/.venv/carrega/lib/python3.9/site-packages/urllib3/connection.py", line 171, in _new_conn
    raise NewConnectionError(
urllib3.exceptions.NewConnectionError: <urllib3.connection.HTTPConnection object at 0x7f411ccbad60>: Failed to establish a new connection: [Errno 111] Connection refused

During handling of the above exception, another exception occurred:

Traceback (most recent call last):
  File "/home/jicg/.venv/carrega/lib/python3.9/site-packages/requests/adapters.py", line 439, in send
    resp = conn.urlopen(
  File "/home/jicg/.venv/carrega/lib/python3.9/site-packages/elasticapm/instrumentation/packages/base.py", line 205, in call_if_sampling
    return wrapped(*args, **kwargs)
  File "/home/jicg/.venv/carrega/lib/python3.9/site-packages/urllib3/connectionpool.py", line 726, in urlopen
    retries = retries.increment(
  File "/home/jicg/.venv/carrega/lib/python3.9/site-packages/urllib3/util/retry.py", line 446, in increment
    raise MaxRetryError(_pool, url, error or ResponseError(cause))
urllib3.exceptions.MaxRetryError: HTTPConnectionPool(host='localhost', port=9000): Max retries exceeded with url: /polycube/v1 (Caused by NewConnectionError('<urllib3.connection.HTTPConnection object at 0x7f411ccbad60>: Failed to establish a new connection: [Errno 111] Connection refused'))

During handling of the above exception, another exception occurred:

Traceback (most recent call last):
  File "/data/jicg/WorkIssues/GUARD/Development/Integration/lcp/lib/polycube.py", line 27, in __init__
    resp_req = get_req(self.endpoint,
  File "/home/jicg/.venv/carrega/lib/python3.9/site-packages/requests/api.py", line 76, in get
    return request('get', url, params=params, **kwargs)
  File "/home/jicg/.venv/carrega/lib/python3.9/site-packages/requests/api.py", line 61, in request
    return session.request(method=method, url=url, **kwargs)
  File "/home/jicg/.venv/carrega/lib/python3.9/site-packages/requests/sessions.py", line 530, in request
    resp = self.send(prep, **send_kwargs)
  File "/home/jicg/.venv/carrega/lib/python3.9/site-packages/elasticapm/instrumentation/packages/base.py", line 205, in call_if_sampling
    return wrapped(*args, **kwargs)
  File "/home/jicg/.venv/carrega/lib/python3.9/site-packages/requests/sessions.py", line 643, in send
    r = adapter.send(request, **kwargs)
  File "/home/jicg/.venv/carrega/lib/python3.9/site-packages/requests/adapters.py", line 516, in send
    raise ConnectionError(e, request=request)
requests.exceptions.ConnectionError: HTTPConnectionPool(host='localhost', port=9000): Max retries exceeded with url: /polycube/v1 (Caused by NewConnectionError('<urllib3.connection.HTTPConnection object at 0x7f411ccbad60>: Failed to establish a new connection: [Errno 111] Connection refused'))
2021-04-15 at 15:31:21 💪   SUCCESS  /code endpoint configured                                                                            💻 __init__.py@routes:35 ⏰ 0:00:00.438628
2021-04-15 at 15:31:21 💪   SUCCESS  /code/{id} endpoint configured                                                                       💻 __init__.py@routes:35 ⏰ 0:00:00.470386
2021-04-15 at 15:31:21 💪   SUCCESS  /config endpoint configured                                                                          💻 __init__.py@routes:35 ⏰ 0:00:00.478390
2021-04-15 at 15:31:21 💪   SUCCESS  /status endpoint configured                                                                          💻 __init__.py@routes:35 ⏰ 0:00:00.486830
2021-04-15 at 15:31:21 💪   SUCCESS  /self/software endpoint configured                                                                   💻 __init__.py@routes:35 ⏰ 0:00:00.495615
2021-04-15 at 15:31:21 💪   SUCCESS  /self/container endpoint configured                                                                  💻 __init__.py@routes:35 ⏰ 0:00:00.502355
2021-04-15 at 15:31:21 💪   SUCCESS  /lxc endpoint configured                                                                             💻 __init__.py@routes:35 ⏰ 0:00:00.509453
2021-04-15 at 15:31:21 💪   SUCCESS  /lcp_son/{id} endpoint configured                                                                    💻 __init__.py@routes:35 ⏰ 0:00:00.519676
2021-04-15 at 15:31:21 💪   SUCCESS  /lcp_son endpoint configured                                                                         💻 __init__.py@routes:35 ⏰ 0:00:00.527294
2021-04-15 at 15:31:21 💪   SUCCESS  /lcp_parent endpoint configured                                                                      💻 __init__.py@routes:35 ⏰ 0:00:00.527975
2021-04-15 at 15:31:21 💪   SUCCESS  /baremetal endpoint configured                                                                       💻 __init__.py@routes:35 ⏰ 0:00:00.535712
2021-04-15 at 15:31:21 💪   SUCCESS  /virtualserver endpoint configured                                                                   💻 __init__.py@routes:35 ⏰ 0:00:00.543528
2021-04-15 at 15:31:21 💪   SUCCESS  /lxc endpoint configured                                                                             💻 __init__.py@routes:35 ⏰ 0:00:00.550839
2021-04-15 at 15:31:21 💪   SUCCESS  /cloud endpoint configured                                                                           💻 __init__.py@routes:35 ⏰ 0:00:00.559079
2021-04-15 at 15:31:21 💪   SUCCESS  /securityFunctions endpoint configured                                                               💻 __init__.py@routes:35 ⏰ 0:00:00.571033
2021-04-15 at 15:31:21 💪   SUCCESS  /self/software endpoint configured                                                                   💻 __init__.py@routes:35 ⏰ 0:00:00.579514
2021-04-15 at 15:31:21 💪   SUCCESS  /self/deployment endpoint configured                                                                 💻 __init__.py@routes:35 ⏰ 0:00:00.587423
2021-04-15 at 15:31:21 💪   SUCCESS  Accept requests at 0.0.0.0:4000                                                                      💻 main.py@<module>:32 ⏰ 0:00:00.701314
