2021-04-19 at 10:49:34 🔖   INFO     Found additional log level customization: 💪   SUCCESS                                                💻 log.py@init:75 ⏰ 0:01:27.707805
2021-04-19 at 10:49:34 🔖   INFO     Found additional log level customization: 👀   WARN                                                   💻 log.py@init:75 ⏰ 0:01:27.708590
2021-04-19 at 10:49:34 🔖   INFO     Found additional log level customization: 🔖   INFO                                                   💻 log.py@init:75 ⏰ 0:01:27.709041
2021-04-19 at 10:49:34 🔖   INFO     Found additional log level customization: ❌   ERROR                                                  💻 log.py@init:75 ⏰ 0:01:27.709480
2021-04-19 at 10:49:34 🔖   INFO     Found additional log level customization: 🎯   NOTICE                                                 💻 log.py@init:75 ⏰ 0:01:27.709914
2021-04-19 at 10:49:34 🔖   INFO     Found additional log level customization: 💩   SPAM                                                   💻 log.py@init:75 ⏰ 0:01:27.710379
2021-04-19 at 10:49:34 🔖   INFO     Found additional log level customization: 📝   VERBOSE                                                💻 log.py@init:75 ⏰ 0:01:27.710866
2021-04-19 at 10:49:34 🔖   INFO     Found additional log level customization: 💥   CRITICAL                                               💻 log.py@init:75 ⏰ 0:01:27.711333
2021-04-19 at 10:49:34 🎯   NOTICE   JWT authentication disabled                                                                          💻 __init__.py@api:38 ⏰ 0:01:27.712034
2021-04-19 at 10:49:34 🎯   NOTICE   HTTPS not set                                                                                        💻 __init__.py@api:44 ⏰ 0:01:27.712455
2021-04-19 at 10:49:34 🎯   NOTICE   Elastic APM disabled                                                                                 💻 __init__.py@api:50 ⏰ 0:01:27.712866
2021-04-19 at 10:49:34 🔖   INFO     Check connection to http://localhost:9000/polycube/v1                                                💻 polycube.py@__init__:25 ⏰ 0:01:27.723632
2021-04-19 at 10:49:34 ❌   ERROR    Connection with polycube at localhost:9000 not possible                                              💻 polycube.py@__init__:31 ⏰ 0:01:27.732529
Traceback (most recent call last):
  File "/home/jicg/.venv/carrega/lib/python3.9/site-packages/urllib3/connection.py", line 159, in _new_conn
    conn = connection.create_connection(
  File "/home/jicg/.venv/carrega/lib/python3.9/site-packages/urllib3/util/connection.py", line 84, in create_connection
    raise err
  File "/home/jicg/.venv/carrega/lib/python3.9/site-packages/urllib3/util/connection.py", line 74, in create_connection
    sock.connect(sa)
ConnectionRefusedError: [Errno 111] Connection refused

During handling of the above exception, another exception occurred:

Traceback (most recent call last):
  File "/home/jicg/.venv/carrega/lib/python3.9/site-packages/urllib3/connectionpool.py", line 670, in urlopen
    httplib_response = self._make_request(
  File "/home/jicg/.venv/carrega/lib/python3.9/site-packages/urllib3/connectionpool.py", line 392, in _make_request
    conn.request(method, url, **httplib_request_kw)
  File "/usr/lib/python3.9/http/client.py", line 1253, in request
    self._send_request(method, url, body, headers, encode_chunked)
  File "/usr/lib/python3.9/http/client.py", line 1299, in _send_request
    self.endheaders(body, encode_chunked=encode_chunked)
  File "/usr/lib/python3.9/http/client.py", line 1248, in endheaders
    self._send_output(message_body, encode_chunked=encode_chunked)
  File "/usr/lib/python3.9/http/client.py", line 1008, in _send_output
    self.send(msg)
  File "/usr/lib/python3.9/http/client.py", line 948, in send
    self.connect()
  File "/home/jicg/.venv/carrega/lib/python3.9/site-packages/urllib3/connection.py", line 187, in connect
    conn = self._new_conn()
  File "/home/jicg/.venv/carrega/lib/python3.9/site-packages/urllib3/connection.py", line 171, in _new_conn
    raise NewConnectionError(
urllib3.exceptions.NewConnectionError: <urllib3.connection.HTTPConnection object at 0x7f2d0fa70880>: Failed to establish a new connection: [Errno 111] Connection refused

During handling of the above exception, another exception occurred:

Traceback (most recent call last):
  File "/home/jicg/.venv/carrega/lib/python3.9/site-packages/requests/adapters.py", line 439, in send
    resp = conn.urlopen(
  File "/home/jicg/.venv/carrega/lib/python3.9/site-packages/elasticapm/instrumentation/packages/base.py", line 205, in call_if_sampling
    return wrapped(*args, **kwargs)
  File "/home/jicg/.venv/carrega/lib/python3.9/site-packages/urllib3/connectionpool.py", line 726, in urlopen
    retries = retries.increment(
  File "/home/jicg/.venv/carrega/lib/python3.9/site-packages/urllib3/util/retry.py", line 446, in increment
    raise MaxRetryError(_pool, url, error or ResponseError(cause))
urllib3.exceptions.MaxRetryError: HTTPConnectionPool(host='localhost', port=9000): Max retries exceeded with url: /polycube/v1 (Caused by NewConnectionError('<urllib3.connection.HTTPConnection object at 0x7f2d0fa70880>: Failed to establish a new connection: [Errno 111] Connection refused'))

During handling of the above exception, another exception occurred:

Traceback (most recent call last):
  File "/data/jicg/WorkIssues/GUARD/Development/Integration/lcp/lib/polycube.py", line 27, in __init__
    resp_req = get_req(self.endpoint,
  File "/home/jicg/.venv/carrega/lib/python3.9/site-packages/requests/api.py", line 76, in get
    return request('get', url, params=params, **kwargs)
  File "/home/jicg/.venv/carrega/lib/python3.9/site-packages/requests/api.py", line 61, in request
    return session.request(method=method, url=url, **kwargs)
  File "/home/jicg/.venv/carrega/lib/python3.9/site-packages/requests/sessions.py", line 530, in request
    resp = self.send(prep, **send_kwargs)
  File "/home/jicg/.venv/carrega/lib/python3.9/site-packages/elasticapm/instrumentation/packages/base.py", line 205, in call_if_sampling
    return wrapped(*args, **kwargs)
  File "/home/jicg/.venv/carrega/lib/python3.9/site-packages/requests/sessions.py", line 643, in send
    r = adapter.send(request, **kwargs)
  File "/home/jicg/.venv/carrega/lib/python3.9/site-packages/requests/adapters.py", line 516, in send
    raise ConnectionError(e, request=request)
requests.exceptions.ConnectionError: HTTPConnectionPool(host='localhost', port=9000): Max retries exceeded with url: /polycube/v1 (Caused by NewConnectionError('<urllib3.connection.HTTPConnection object at 0x7f2d0fa70880>: Failed to establish a new connection: [Errno 111] Connection refused'))
2021-04-19 at 10:49:34 💪   SUCCESS  /code endpoint configured                                                                            💻 __init__.py@routes:35 ⏰ 0:01:27.802626
2021-04-19 at 10:49:34 💪   SUCCESS  /code/{id} endpoint configured                                                                       💻 __init__.py@routes:35 ⏰ 0:01:27.861134
2021-04-19 at 10:49:34 💪   SUCCESS  /config endpoint configured                                                                          💻 __init__.py@routes:35 ⏰ 0:01:27.883740
2021-04-19 at 10:49:34 💪   SUCCESS  /status endpoint configured                                                                          💻 __init__.py@routes:35 ⏰ 0:01:27.904905
2021-04-19 at 10:49:34 💪   SUCCESS  /self/software endpoint configured                                                                   💻 __init__.py@routes:35 ⏰ 0:01:27.934545
2021-04-19 at 10:49:34 💪   SUCCESS  /self/container endpoint configured                                                                  💻 __init__.py@routes:35 ⏰ 0:01:27.960904
2021-04-19 at 10:49:34 💪   SUCCESS  /lxc endpoint configured                                                                             💻 __init__.py@routes:35 ⏰ 0:01:27.986576
2021-04-19 at 10:49:34 💪   SUCCESS  /lcp_son/{id} endpoint configured                                                                    💻 __init__.py@routes:35 ⏰ 0:01:28.013137
2021-04-19 at 10:49:35 💪   SUCCESS  /lcp_son endpoint configured                                                                         💻 __init__.py@routes:35 ⏰ 0:01:28.038077
2021-04-19 at 10:49:35 💪   SUCCESS  /lcp_parent endpoint configured                                                                      💻 __init__.py@routes:35 ⏰ 0:01:28.039637
2021-04-19 at 10:49:35 💪   SUCCESS  /baremetal endpoint configured                                                                       💻 __init__.py@routes:35 ⏰ 0:01:28.067503
2021-04-19 at 10:49:35 💪   SUCCESS  /virtualserver endpoint configured                                                                   💻 __init__.py@routes:35 ⏰ 0:01:28.095425
2021-04-19 at 10:49:35 💪   SUCCESS  /lxc endpoint configured                                                                             💻 __init__.py@routes:35 ⏰ 0:01:28.120690
2021-04-19 at 10:49:35 💪   SUCCESS  /cloud endpoint configured                                                                           💻 __init__.py@routes:35 ⏰ 0:01:28.148009
2021-04-19 at 10:49:35 💪   SUCCESS  /securityFunctions endpoint configured                                                               💻 __init__.py@routes:35 ⏰ 0:01:28.174529
2021-04-19 at 10:49:35 💪   SUCCESS  /self/software endpoint configured                                                                   💻 __init__.py@routes:35 ⏰ 0:01:28.201569
2021-04-19 at 10:49:35 💪   SUCCESS  /self/deployment endpoint configured                                                                 💻 __init__.py@routes:35 ⏰ 0:01:28.228872
2021-04-19 at 10:49:35 💪   SUCCESS  /self endpoint configured                                                                            💻 __init__.py@routes:35 ⏰ 0:01:28.230755
